Traceback (most recent call last):
  File "C:\Users\sergi\AppData\Local\Temp\ipykernel_271252\2069214660.py", line 19, in wandb_train
    bst.fit(X_train, y_train)
  File "c:\Users\sergi\anaconda3\envs\olx\Lib\site-packages\catboost\core.py", line 5827, in fit
    return self._fit(X, y, cat_features, text_features, embedding_features, None, sample_weight, None, None, None, None, baseline,
           ^^^^^^^^^^^^^^^^^^^^^^^^^^^^^^^^^^^^^^^^^^^^^^^^^^^^^^^^^^^^^^^^^^^^^^^^^^^^^^^^^^^^^^^^^^^^^^^^^^^^^^^^^^^^^^^^^^^^^^^
  File "c:\Users\sergi\anaconda3\envs\olx\Lib\site-packages\catboost\core.py", line 2400, in _fit
    self._train(
  File "c:\Users\sergi\anaconda3\envs\olx\Lib\site-packages\catboost\core.py", line 1780, in _train
    self._object._train(train_pool, test_pool, params, allow_clear_pool, init_model._object if init_model else None)
  File "_catboost.pyx", line 4833, in _catboost._CatBoost._train
  File "_catboost.pyx", line 4882, in _catboost._CatBoost._train
_catboost.CatBoostError: bad allocation